# 예외(Exception)

예외란, 정상적인 상황에서 벗어난 모든 예외적인 상황이다.

## 1. 예외 발생시키기 - throw

C++ 에서는 예외가 발생하였다는 사실을 throw 문을 사용해 명시적으로 나타낸다.

~~~C++
template <typename T>
class Vector {
    private:
        T* data_;
        size_t size_;

    public:
        Vector(size_t size) : size_(size) {
            data_ = new T[size_];
            for (int i = 0; i < size_; i++) {
                data_[i] = 3;
            }
        }

        const T& at(size_t index) const {
            if (index >= size_) {
                // C++ 에는 예외를 던지고 싶다면, throw 로 예외로 전달하고 싶은 객체를 써주면 된다.
                // overflow_error, length_error, runtime_error 등등
                throw out_of_range("vector 의 index 가 범위를 초과하였습니다.");
            }
            return data_[index];
        }
        ~Vector() { delete[] data_; }
};
~~~

예외를 throw 하게 되면, throw 한 위치에서 즉시 함수가 종료되고, 예외 처리하는 부분까지 점프된다. 따라서 throw 밑에 있는 모든 문장은 실행되지 않는다. 한 가지 중요한 점은 이렇게 함수에서 예외 처리하는 부분에 도달하기 까지 함수를 빠져나가면서, stack 에 생성되었던 객체들을 빠짐없이 소멸시켜 준다는 것이다. 따라서 예외가 발생하여도 사용하고 있는 자원들을 제대로 소멸시킬 수 있다.

## 2. 예외 처리 하기 - try 와 catch

~~~C++
#include <iostream>
#include <stdexcept>

template <typename T>
class Vector {
    private:
        T* data_;
        size_t size_;

    public:
        Vector(size_t size) : size_(size) {
            data_ = new T[size_];
            for (int i = 0; i < size_; i++) {
                data_[i] = 3;
            }
        }

        const T& at(size_t index) const {
            if (index >= size_) {
                throw out_of_range("vector 의 index 가 범위를 초과하였습니다.");
            }
            return data_[index];
        }
        ~Vector() { delete[] data_; }
};

int main() {
    Vector<int> vec(3);

    int index, data = 0;
    std::cin >> index;

    try {
        // try 안에서 무언가 예외가 발생할만한 코드가 실행
        data = vec.at(index);
        // 예외가 발생할 경우 그 즉시 stack 에 생성된 모든 객체들의 소멸자들이 호출되고, 가장 가까운 catch 문으로 점프
    } catch (std::out_of_range& e) { // catch 문 안에 정의된 예외의 꼴에 맞는 객체를 받게 된다.
        std::cout << "예외 발생 ! " << e.what() << std::endl;
    }
    // 예외가 발생하지 않았다면 3을 이 출력되고, 예외가 발생하였다면 원래 data 에
    // 들어가 있던 0 이 출력된다.
    std::cout << "읽은 데이터 : " << data << std::endl;
}
~~~

## 3. 스택 풀기 (stack unwinding)

스택 풀기란, catch 로 점프 하면서 스택 상에서 정의된 객체들을 소멸시키는 과정을 말한다.

~~~C++
#include <iostream>
#include <stdexcept>

class Resource {
    private:
        int id_;
    public:
        Resource(int id) : id_(id) {}
        ~Resource() { std::cout << "리소스 해제 : " << id_ << std::endl; }
};

int func3() {
    Resource r(3);
    throw std::runtime_error("Exception from 3!\n"); // ·············(1)
}

int func2() {
    Resource r(2);
    func3();
    std::cout << "실행" << std::endl;
    return 0;
}

int func1() {
    Resource r(1);
    func2();
    std::cout << "실행" << std::endl;
    return 0;
}

int main() {
    try {
        func1();
    } catch (std::exception& e) {
        std::cout << "Exception : " << e.what();
    }
}

/*
(1) 이 있을 경우                          (1) 이 없을 경우
리소스 해제 : 3                            리소스 해제 : 3
리소스 해제 : 2                            실행!
리소스 해제 : 1                            리소스 해제 : 2
Exception : Exception from 3!             실행!
                                          리소스 해제 : 1
*/
~~~

예외를 생성자에서 던질 때 생성자에서 예외가 발생 시에 소멸자가 호출되지 않는다 라는 점을 주의해야 한다. 따라서, 만일 예외를 던지기 이전에 획득한 자원이 있다면 catch 에서 잘 해제시켜 줘야만 한다.

## 4. 모든 종류의 예외 받기

한 개의 try 안에 받고자 하는 모든 종류의 예외를 catch 문으로 주렁 주렁 달면 된다.

한 가지 주의 점은 기반 클래스와 파생 클래스의 경우 처리하는 방식이다.

~~~C++
try {
    func(c);
} catch (Parent& p) {
    std::cout << p.what();
} catch (Child& c) {
    std::cout << c.what();
}

// Child 객체를 throw 하였을 때에는 예상과는 다르게, Child 를 받는 catch 문이 아닌, Parent 를 받는 catch 문이 실행된다.
Parent& p = Child(); // 가 가능하기 때문이다.

Child &c = Parent(); // 이것은 불가능 하기 때문에 Parent와 Child catch문의 순서를 바꿔준다.

try {
    func(c);
} catch (Child& c) {
    std::cout << c.what();
} catch (Parent& p) {
    std::cout << p.what();
}
~~~

표준 라이브러리의 유용한 함수들(nested_exception 등) 을 사용할 수 있기 때문에 일반적으로 예외 객체는 std::exception 을 상속 받는 것이 좋다.

## 5. 모든 예외 받기

언제나 예외를 던지는 코드가 있다면 적절하게 받아내는 것이 중요하다. 이때 예외 객체 하나 하나 처리할 필요 없이 그냥 나머지 전부다! 처리할 때는

~~~C++
try {
    func(c);
}catch (...) { // catch(...) 에서 try 안에서 발생한 모든 예외들을 받게 된다.
    std::cout << "Default Catch!" << std::endl;
}
~~~

템플릿으로 정의되는 클래스의 경우 어떠한 방식으로 템플릿이 인스턴스화 되냐에 따라서 던지는 예외의 종류가 달라질 수 있다. 이 때문에 해당 객체의 catch 에서는 모든 예외 객체를 고려해야 한다.

## 6. 예외를 발생시키지 않는 함수 - noexcept

만약에 어떤 함수가 예외를 발생시키지 않는다면 noexcept 를 통해 명시할 수 있다.

noexcept 키워드를 붙였다고 해서, 함수가 예외를 절대로 던지지 않는다는 것은 아니다. 컴파일러는 noexcept 키워드가 붙은 함수가 이 친구는 예외를 발생시키지 않는구나 라고 곧이곧대로 믿고, 그대로 컴파일 하게된다.

대신 noexcept 로 명시된 함수가 예외를 발생시키게 된다면 예외가 제대로 처리되지 않고 프로그램이 종료된다.

~~~C++
#include <iostream>

int foo() noexcept {}

int bar() noexcept { throw 1; }

int main() {
    foo();
    try {
        bar();
    } catch (int x) {
        std::cout << "Error : " << x << std::endl;
    }
}
~~~

noexcept 키워드를 붙이는 이유는  컴파일러가 어떤 함수가 절대로 예외를 발생시키지 않는다는 사실을 안다면, 여러가지 추가적인 최적화를 수행할 수 있게 하기 위해서 이다.
